[2025-03-21T19:05:59.721+0000] {local_task_job_runner.py:123} INFO - ::group::Pre task execution logs
[2025-03-21T19:05:59.784+0000] {taskinstance.py:2614} INFO - Dependencies all met for dep_context=non-requeueable deps ti=<TaskInstance: weather-data-pipeline.create_insert_mart_tables scheduled__2025-03-21T18:00:00+00:00 [queued]>
[2025-03-21T19:05:59.819+0000] {taskinstance.py:2614} INFO - Dependencies all met for dep_context=requeueable deps ti=<TaskInstance: weather-data-pipeline.create_insert_mart_tables scheduled__2025-03-21T18:00:00+00:00 [queued]>
[2025-03-21T19:05:59.819+0000] {taskinstance.py:2867} INFO - Starting attempt 1 of 2
[2025-03-21T19:05:59.851+0000] {taskinstance.py:2890} INFO - Executing <Task(PythonOperator): create_insert_mart_tables> on 2025-03-21 18:00:00+00:00
[2025-03-21T19:05:59.863+0000] {warnings.py:112} WARNING - /home/***/.local/lib/python3.12/site-packages/***/task/task_runner/standard_task_runner.py:70: DeprecationWarning: This process (pid=1527) is multi-threaded, use of fork() may lead to deadlocks in the child.
  pid = os.fork()

[2025-03-21T19:05:59.866+0000] {standard_task_runner.py:72} INFO - Started process 1531 to run task
[2025-03-21T19:05:59.867+0000] {standard_task_runner.py:104} INFO - Running: ['***', 'tasks', 'run', 'weather-data-pipeline', 'create_insert_mart_tables', 'scheduled__2025-03-21T18:00:00+00:00', '--job-id', '154', '--raw', '--subdir', 'DAGS_FOLDER/weather-data-pipeline.py', '--cfg-path', '/tmp/tmp9v8pdk6e']
[2025-03-21T19:05:59.871+0000] {standard_task_runner.py:105} INFO - Job 154: Subtask create_insert_mart_tables
[2025-03-21T19:06:00.238+0000] {task_command.py:467} INFO - Running <TaskInstance: weather-data-pipeline.create_insert_mart_tables scheduled__2025-03-21T18:00:00+00:00 [running]> on host c25e9da6226b
[2025-03-21T19:06:00.390+0000] {taskinstance.py:3134} INFO - Exporting env vars: AIRFLOW_CTX_DAG_OWNER='***' AIRFLOW_CTX_DAG_ID='weather-data-pipeline' AIRFLOW_CTX_TASK_ID='create_insert_mart_tables' AIRFLOW_CTX_EXECUTION_DATE='2025-03-21T18:00:00+00:00' AIRFLOW_CTX_TRY_NUMBER='1' AIRFLOW_CTX_DAG_RUN_ID='scheduled__2025-03-21T18:00:00+00:00'
[2025-03-21T19:06:00.392+0000] {taskinstance.py:732} INFO - ::endgroup::
[2025-03-21T19:06:00.444+0000] {base.py:84} INFO - Retrieving connection 'rizqi-neon'
[2025-03-21T19:06:01.198+0000] {taskinstance.py:3313} ERROR - Task failed with exception
Traceback (most recent call last):
  File "/home/airflow/.local/lib/python3.12/site-packages/airflow/models/taskinstance.py", line 768, in _execute_task
    result = _execute_callable(context=context, **execute_callable_kwargs)
             ^^^^^^^^^^^^^^^^^^^^^^^^^^^^^^^^^^^^^^^^^^^^^^^^^^^^^^^^^^^^^
  File "/home/airflow/.local/lib/python3.12/site-packages/airflow/models/taskinstance.py", line 734, in _execute_callable
    return ExecutionCallableRunner(
           ^^^^^^^^^^^^^^^^^^^^^^^^
  File "/home/airflow/.local/lib/python3.12/site-packages/airflow/utils/operator_helpers.py", line 252, in run
    return self.func(*args, **kwargs)
           ^^^^^^^^^^^^^^^^^^^^^^^^^^
  File "/home/airflow/.local/lib/python3.12/site-packages/airflow/models/baseoperator.py", line 424, in wrapper
    return func(self, *args, **kwargs)
           ^^^^^^^^^^^^^^^^^^^^^^^^^^^
  File "/home/airflow/.local/lib/python3.12/site-packages/airflow/operators/python.py", line 238, in execute
    return_value = self.execute_callable()
                   ^^^^^^^^^^^^^^^^^^^^^^^
  File "/home/airflow/.local/lib/python3.12/site-packages/airflow/operators/python.py", line 256, in execute_callable
    return runner.run(*self.op_args, **self.op_kwargs)
           ^^^^^^^^^^^^^^^^^^^^^^^^^^^^^^^^^^^^^^^^^^^
  File "/home/airflow/.local/lib/python3.12/site-packages/airflow/utils/operator_helpers.py", line 252, in run
    return self.func(*args, **kwargs)
           ^^^^^^^^^^^^^^^^^^^^^^^^^^
  File "/opt/airflow/dags/weather-data-pipeline.py", line 316, in create_insert_mart_tables
    cur.execute("""
psycopg2.errors.UniqueViolation: duplicate key value violates unique constraint "mart_daily_weather_pkey"
DETAIL:  Key (date, area)=(2025-03-26, Jakarta) already exists.

[2025-03-21T19:06:01.269+0000] {taskinstance.py:1226} INFO - Marking task as UP_FOR_RETRY. dag_id=weather-data-pipeline, task_id=create_insert_mart_tables, run_id=scheduled__2025-03-21T18:00:00+00:00, execution_date=20250321T180000, start_date=20250321T190559, end_date=20250321T190601
[2025-03-21T19:06:01.385+0000] {taskinstance.py:341} INFO - ::group::Post task execution logs
[2025-03-21T19:06:01.387+0000] {standard_task_runner.py:124} ERROR - Failed to execute job 154 for task create_insert_mart_tables (duplicate key value violates unique constraint "mart_daily_weather_pkey"
DETAIL:  Key (date, area)=(2025-03-26, Jakarta) already exists.
; 1531)
Traceback (most recent call last):
  File "/home/airflow/.local/lib/python3.12/site-packages/airflow/task/task_runner/standard_task_runner.py", line 117, in _start_by_fork
    ret = args.func(args, dag=self.dag)
          ^^^^^^^^^^^^^^^^^^^^^^^^^^^^^
  File "/home/airflow/.local/lib/python3.12/site-packages/airflow/cli/cli_config.py", line 49, in command
    return func(*args, **kwargs)
           ^^^^^^^^^^^^^^^^^^^^^
  File "/home/airflow/.local/lib/python3.12/site-packages/airflow/utils/cli.py", line 116, in wrapper
    return f(*args, **kwargs)
           ^^^^^^^^^^^^^^^^^^
  File "/home/airflow/.local/lib/python3.12/site-packages/airflow/cli/commands/task_command.py", line 483, in task_run
    task_return_code = _run_task_by_selected_method(args, _dag, ti)
                       ^^^^^^^^^^^^^^^^^^^^^^^^^^^^^^^^^^^^^^^^^^^^
  File "/home/airflow/.local/lib/python3.12/site-packages/airflow/cli/commands/task_command.py", line 256, in _run_task_by_selected_method
    return _run_raw_task(args, ti)
           ^^^^^^^^^^^^^^^^^^^^^^^
  File "/home/airflow/.local/lib/python3.12/site-packages/airflow/cli/commands/task_command.py", line 341, in _run_raw_task
    return ti._run_raw_task(
           ^^^^^^^^^^^^^^^^^
  File "/home/airflow/.local/lib/python3.12/site-packages/airflow/utils/session.py", line 97, in wrapper
    return func(*args, session=session, **kwargs)
           ^^^^^^^^^^^^^^^^^^^^^^^^^^^^^^^^^^^^^^
  File "/home/airflow/.local/lib/python3.12/site-packages/airflow/models/taskinstance.py", line 3006, in _run_raw_task
    return _run_raw_task(
           ^^^^^^^^^^^^^^
  File "/home/airflow/.local/lib/python3.12/site-packages/airflow/models/taskinstance.py", line 274, in _run_raw_task
    TaskInstance._execute_task_with_callbacks(
  File "/home/airflow/.local/lib/python3.12/site-packages/airflow/models/taskinstance.py", line 3161, in _execute_task_with_callbacks
    result = self._execute_task(context, task_orig)
             ^^^^^^^^^^^^^^^^^^^^^^^^^^^^^^^^^^^^^^
  File "/home/airflow/.local/lib/python3.12/site-packages/airflow/models/taskinstance.py", line 3185, in _execute_task
    return _execute_task(self, context, task_orig)
           ^^^^^^^^^^^^^^^^^^^^^^^^^^^^^^^^^^^^^^^
  File "/home/airflow/.local/lib/python3.12/site-packages/airflow/models/taskinstance.py", line 768, in _execute_task
    result = _execute_callable(context=context, **execute_callable_kwargs)
             ^^^^^^^^^^^^^^^^^^^^^^^^^^^^^^^^^^^^^^^^^^^^^^^^^^^^^^^^^^^^^
  File "/home/airflow/.local/lib/python3.12/site-packages/airflow/models/taskinstance.py", line 734, in _execute_callable
    return ExecutionCallableRunner(
           ^^^^^^^^^^^^^^^^^^^^^^^^
  File "/home/airflow/.local/lib/python3.12/site-packages/airflow/utils/operator_helpers.py", line 252, in run
    return self.func(*args, **kwargs)
           ^^^^^^^^^^^^^^^^^^^^^^^^^^
  File "/home/airflow/.local/lib/python3.12/site-packages/airflow/models/baseoperator.py", line 424, in wrapper
    return func(self, *args, **kwargs)
           ^^^^^^^^^^^^^^^^^^^^^^^^^^^
  File "/home/airflow/.local/lib/python3.12/site-packages/airflow/operators/python.py", line 238, in execute
    return_value = self.execute_callable()
                   ^^^^^^^^^^^^^^^^^^^^^^^
  File "/home/airflow/.local/lib/python3.12/site-packages/airflow/operators/python.py", line 256, in execute_callable
    return runner.run(*self.op_args, **self.op_kwargs)
           ^^^^^^^^^^^^^^^^^^^^^^^^^^^^^^^^^^^^^^^^^^^
  File "/home/airflow/.local/lib/python3.12/site-packages/airflow/utils/operator_helpers.py", line 252, in run
    return self.func(*args, **kwargs)
           ^^^^^^^^^^^^^^^^^^^^^^^^^^
  File "/opt/airflow/dags/weather-data-pipeline.py", line 316, in create_insert_mart_tables
    cur.execute("""
psycopg2.errors.UniqueViolation: duplicate key value violates unique constraint "mart_daily_weather_pkey"
DETAIL:  Key (date, area)=(2025-03-26, Jakarta) already exists.

[2025-03-21T19:06:01.503+0000] {local_task_job_runner.py:266} INFO - Task exited with return code 1
[2025-03-21T19:06:01.835+0000] {taskinstance.py:3901} INFO - 0 downstream tasks scheduled from follow-on schedule check
[2025-03-21T19:06:01.838+0000] {local_task_job_runner.py:245} INFO - ::endgroup::
